<?xml version="1.0"?>
<robot name="gripper_placer"
       xmlns:xacro="http://ros.org/wiki/xacro">

  <xacro:arg name="with_gripper_instead_of_forks" default="true" />
  <xacro:arg name="stl_collision" default="false" />
  <xacro:if value="$(arg with_gripper_instead_of_forks)">
    <xacro:property name="tool_offset_z" value="0.11485" />
    <xacro:property name="tool_rotation_z" value="0" />
    <xacro:property name="tool_stl_path" value="package://hydra/models/gripper_placer/meshes/gripper_pad_v2_part.stl" />
    <!--xacro:property name="tool_stl_path" value="package://hydra/models/gripper_placer/meshes/gripper_pad_slot_version.stl" /-->
  </xacro:if>  
  <xacro:unless value="$(arg with_gripper_instead_of_forks)">
    <xacro:property name="tool_offset_z" value="0" />
    <xacro:property name="tool_rotation_z" value="${pi/2}" />
    <xacro:property name="tool_stl_path" value="package://hydra/models/gripper_placer/meshes/forks.stl" />
    <!--xacro:property name="tool_stl_path" value="package://hydra/models/gripper_placer/meshes/forks_slot_version.stl" /-->
  </xacro:unless>
    

  <!-- Switch between EffortJointInterface and PositionJointInterface, still requires change in yaml files -->
  <xacro:arg name="using_position_not_effort" default="false" />
  <xacro:if value="$(arg using_position_not_effort)">
    <xacro:property name="joint_interface" value="PositionJointInterface" />
  </xacro:if>
  <xacro:unless value="$(arg using_position_not_effort)">
    <xacro:property name="joint_interface" value="EffortJointInterface" />
  </xacro:unless>

  <!-- Constants for gripper joint controllers -->
  <xacro:property name="effort_limit" value="100000" />
  <xacro:property name="gripper_max_vel" value="0.0" />  <!-- Default is 0.01 -->
  <xacro:property name="gripper_min_depth" value="0.0001" />  <!-- Default is 0 -->
  <xacro:property name="gripper_kp" value="1e11" />  <!-- Default is 1e12 -->
  <xacro:property name="gripper_kd" value="1e5" />  <!-- Default is 1 -->
  <xacro:property name="gripper_mu1" value="1" />  <!-- Default is 1, range is supposedly 0 to 1 (according to SDF) -->
  <xacro:property name="gripper_mu2" value="1" />  <!-- Default is 1, range is supposedly 0 to 1 (according to SDF) -->
  <xacro:property name="gripper_fdir1" value="0 0 0" />  <!-- Default is 0 0 0 -->

  <!-- Variable for the scale used when importing STL -->
  <xacro:property name="stl_scale" value="0.0254" />  <!-- 0.0393701 -->

  <xacro:macro name="inertial_values">
    <inertial>
      <mass value="0.1" />
      <inertia ixx="0.01" ixy="0.0" ixz="0.0" iyy="0.02" iyz="0.0" izz="0.02" />
    </inertial>
  </xacro:macro>

  <xacro:macro name="origin_and_geometry">
    <xacro:if value="$(arg stl_collision)">
      <origin xyz="0 0 ${tool_offset_z}" rpy="0 0 ${pi}" />
      <geometry>
	<mesh filename="${tool_stl_path}" scale="${stl_scale} ${stl_scale} ${stl_scale}" />
      </geometry>
    </xacro:if>
    <xacro:unless value="$(arg stl_collision)">	  
      <origin xyz="0 0 .15" rpy="0 0 ${pi}" />
      <geometry>
	<box size=".10 .01 .07" />
      </geometry>
    </xacro:unless>
  </xacro:macro>

  <!-- Phantom link for center of gripper -->
  <link name="gripper_center" >
    <inertial>
      <mass value="0.01"/>
      <inertia ixx="0.0001" ixy="0.0" ixz="0.0" iyy="0.0001" iyz="0.0" izz="0.0001"/>
    </inertial>
  </link>

  <!-- One side of gripper -->
  <link name="side_p" >
    <visual>
      <xacro:origin_and_geometry />
    </visual>
    <collision>
      <xacro:origin_and_geometry />
    </collision>
    <xacro:inertial_values />
  </link>

  <!-- Second side of gripper -->
  <xacro:if value="$(arg with_gripper_instead_of_forks)">  
    <link name="side_d" >
    <visual>
      <xacro:origin_and_geometry />
    </visual>
    <collision>
      <xacro:origin_and_geometry />
    </collision>
    <xacro:inertial_values />
    </link>

    <xacro:unless value="$(arg stl_collision)">
      <link name="fake_block" >
	<!--
	<visual>
	  <geometry>
	    <box size=".14 .01 .07" />
	  </geometry>
	  </visual>
	  -->
	<collision>
	  <geometry>
	    <box size=".14 .01 .07" />
	  </geometry>
	</collision>
	<xacro:inertial_values />
      </link>
      <joint name="fake_block_joint" type="fixed">
	<origin xyz="0 0.005 .452" rpy="0 0 0" />
	<parent link="side_d" />
	<child link="fake_block" />
      </joint>      
    </xacro:unless>
  

    <!-- Prismatic joint -->
    <joint name="gripper_joint_p" type="prismatic">
      <origin xyz="0 0.038 0" rpy="0 0 0" />
      <axis xyz="0 1 0" />
      <parent link="gripper_center" />
      <child link="side_p" />
      <limit effort="${effort_limit}" lower="-100" upper="100" velocity="0.5"/>
    </joint>
    
    <joint name="gripper_joint_d" type="prismatic">
      <origin xyz="0 -0.038 0" rpy="0 0 0" />
      <axis xyz="0 1 0" />
      <parent link="gripper_center" />
      <child link="side_d" />
      <limit effort="${effort_limit}" lower="-100" upper="100" velocity="0.5"/>
    </joint>

    <!-- Prismatic joint -->
    <!--joint name="gripper_joint_p" type="fixed">
	<origin xyz="0 0 0" rpy="0 0 0" />
	<parent link="gripper_center" />
	<child link="side_p" />
	</joint>
	
	<joint name="gripper_joint_d" type="fixed">
	<origin xyz="0 0 0" rpy="0 0 0" />
	<parent link="gripper_center" />
	<child link="side_d" />
	</joint-->

    <!-- Transmission for ROS control -->
    <transmission name="gripper_joint_transmission_p">
      <type>transmission_interface/SimpleTransmission</type>
      <joint name="gripper_joint_p">
	<hardwareInterface>hardware_interface/${joint_interface}</hardwareInterface>
      </joint>
      <actuator name="gripper_joint_motor_p">
	<hardwareInterface>hardware_interface/${joint_interface}</hardwareInterface>
	<mechanicalReduction>1</mechanicalReduction>
      </actuator>
    </transmission>
    
    <transmission name="gripper_joint_transmission_d">
      <type>transmission_interface/SimpleTransmission</type>
      <joint name="gripper_joint_d">
	<hardwareInterface>hardware_interface/${joint_interface}</hardwareInterface>
      </joint>
      <actuator name="gripper_joint_motor_d">
	<hardwareInterface>hardware_interface/${joint_interface}</hardwareInterface>
	<mechanicalReduction>1</mechanicalReduction>
      </actuator>
    </transmission>

  
    <gazebo reference="side_d">
      <kp>${gripper_kp}</kp>
      <kd>${gripper_kd}</kd>
      <maxVel>${gripper_max_vel}</maxVel>  <!-- Default is 0.01 -->
      <minDepth>${gripper_min_depth}</minDepth>
      <mu1>${gripper_mu1}</mu1>
      <mu2>${gripper_mu2}</mu2>
      <fdir1>${gripper_fdir1}</fdir1>
    </gazebo>
    
  </xacro:if>  <!-- End branch for with_gripper_instead_of_forks -->


  <!-- Gazebo tag for hopefully changing physics engine properties to work -->
  <gazebo reference="side_p">
    <kp>${gripper_kp}</kp>
    <kd>${gripper_kd}</kd>
    <maxVel>${gripper_max_vel}</maxVel>  <!-- Default is 0.01 -->
    <minDepth>${gripper_min_depth}</minDepth>
    <mu1>${gripper_mu1}</mu1>
    <mu2>${gripper_mu2}</mu2>
    <fdir1>${gripper_fdir1}</fdir1>
  </gazebo>
  

  <xacro:unless value="$(arg with_gripper_instead_of_forks)">  
    <!-- Fixed joint for forks -->
    <joint name="gripper_joint_p" type="fixed">
      <origin xyz="0 0 0" rpy="0 0 0" />
      <parent link="gripper_center" />
      <child link="side_p" />
    </joint>
  </xacro:unless>

</robot>
