<?xml version="1.0" ?>
<!-- =================================================================================== -->
<!-- |    This document was autogenerated by xacro from gripper_placer.urdf.xacro      | -->
<!-- |    EDITING THIS FILE BY HAND IS NOT RECOMMENDED                                 | -->
<!-- =================================================================================== -->
<robot name="gripper_placer" xmlns:xacro="http://ros.org/wiki/xacro">
  <!-- Default is 0.01 -->
  <!-- 0.0393701 -->
  <!-- Phantom link for center of gripper -->
  <link name="gripper_center">
    <inertial>
      <mass value="0.01"/>
      <inertia ixx="0.0001" ixy="0.0" ixz="0.0" iyy="0.0001" iyz="0.0" izz="0.0001"/>
    </inertial>
  </link>
  <!-- One side of gripper -->
  <link name="side_p">
    <visual>
      <origin rpy="0 0 0" xyz="0 0 0.11485"/>
      <geometry>
        <mesh filename="package://hydra/models/gripper_placer/meshes/gripper_pad_v2.stl" scale="0.0254 0.0254 0.0254"/>
      </geometry>
    </visual>
    <collision>
      <origin rpy="0 0 0" xyz="0 0 0.11485"/>
      <geometry>
        <mesh filename="package://hydra/models/gripper_placer/meshes/gripper_pad_v2.stl" scale="0.0254 0.0254 0.0254"/>
      </geometry>
    </collision>
    <inertial>
      <mass value="0.001"/>
      <inertia ixx="0.01" ixy="0.0" ixz="0.0" iyy="0.02" iyz="0.0" izz="0.02"/>
    </inertial>
  </link>
  <!-- Second side of gripper -->
  <link name="side_d">
    <visual>
      <origin rpy="0 0 3.14159265359" xyz="0 0 0.11485"/>
      <!--origin xyz="0 0.04185 0" rpy="0 0 ${pi}" /-->
      <geometry>
        <mesh filename="package://hydra/models/gripper_placer/meshes/gripper_pad_v2.stl" scale="0.0254 0.0254 0.0254"/>
      </geometry>
    </visual>
    <collision>
      <origin rpy="0 0 3.14159265359" xyz="0 0 0.11485"/>
      <geometry>
        <mesh filename="package://hydra/models/gripper_placer/meshes/gripper_pad_v2.stl" scale="0.0254 0.0254 0.0254"/>
      </geometry>
    </collision>
    <inertial>
      <mass value="0.001"/>
      <inertia ixx="0.01" ixy="0.0" ixz="0.0" iyy="0.02" iyz="0.0" izz="0.02"/>
    </inertial>
  </link>
  <!-- Prismatic joint -->
  <joint name="gripper_joint_p" type="prismatic">
    <origin rpy="0 0 0" xyz="0 0 0"/>
    <axis xyz="0 1 0"/>
    <parent link="gripper_center"/>
    <child link="side_p"/>
    <limit effort="5000" lower="-100" upper="100" velocity="0.5"/>
  </joint>
  <joint name="gripper_joint_d" type="prismatic">
    <origin rpy="0 0 0" xyz="0 0 0"/>
    <axis xyz="0 1 0"/>
    <parent link="gripper_center"/>
    <child link="side_d"/>
    <limit effort="5000" lower="-100" upper="100" velocity="0.5"/>
  </joint>
  <!-- Prismatic joint -->
  <!--joint name="gripper_joint_p" type="fixed">
    <origin xyz="0 0 0" rpy="0 0 0" />
    <parent link="gripper_center" />
    <child link="side_p" />
  </joint>
  
  <joint name="gripper_joint_d" type="fixed">
    <origin xyz="0 0 0" rpy="0 0 0" />
    <parent link="gripper_center" />
    <child link="side_d" />
    </joint-->
  <transmission name="gripper_joint_transmission_p">
    <type>transmission_interface/SimpleTransmission</type>
    <joint name="gripper_joint_p">
      <hardwareInterface>hardware_interface/PositionJointInterface</hardwareInterface>
    </joint>
    <actuator name="gripper_joint_motor_p">
      <hardwareInterface>hardware_interface/PositionJointInterface</hardwareInterface>
      <mechanicalReduction>1</mechanicalReduction>
    </actuator>
  </transmission>
  <transmission name="gripper_joint_transmission_d">
    <type>transmission_interface/SimpleTransmission</type>
    <joint name="gripper_joint_d">
      <hardwareInterface>hardware_interface/PositionJointInterface</hardwareInterface>
    </joint>
    <actuator name="gripper_joint_motor_d">
      <hardwareInterface>hardware_interface/PositionJointInterface</hardwareInterface>
      <mechanicalReduction>1</mechanicalReduction>
    </actuator>
  </transmission>
  <!-- Gazebo tag for hopefully changing physics engine properties to work -->
  <gazebo>
    <maxVel>0</maxVel>
    <minDepth>0.001</minDepth>
  </gazebo>
</robot>

